<?xml version = "1.0"?>
<robot xmlns:xacro="http://www.ros.org/wiki.xacro" name = "robot" >

<xacro:include filename="inertial.xacro"/>
<xacro:property name="wheel_radius" value="0.1"/>
<xacro:property name="wheel_length" value="0.05"/>
<xacro:property name="wheel_mass" value="0.5"/>
<xacro:property name="damping" value="0.1"/>
<xacro:property name="friction" value="0.5"/>

 <material name = "grey">
     <color rgba = "0.7 0.7 0.7 1" />
    </material>

    <material name = "green">
     <color rgba = "0 0.6 0 1" />
    </material>

    <material name = "white">
     <color rgba = "1 1 1 1" />
    </material>

    <material name = "black">
     <color rgba = "0 0 0 1" />
    </material>

    <material name = "yellow">
     <color rgba = "0.7 0.9 0 1" />
    </material>
    
    <link name="base_footprint" />

    <joint name="base_joint" type="fixed">
        <parent link="base_footprint"/>
        <child link="base_link"/>
        <origin xyz = "0 0 0.1" rpy="0 0 0"/>
    </joint>

     <link name = "base_link">
        <visual>
            <geometry>
                <box size = "0.6 0.4 0.2" />
            </geometry>
            <origin xyz = "0 0 0.1" rpy = "0 0 0" />
            <material name = "yellow" />
        </visual>

        <collision>
            <geometry>
                <box size = "0.6 0.4 0.2" />
            </geometry>
            <origin xyz = "0 0 0.1" rpy = "0 0 0" />
        </collision>

        <xacro:inertial_box mass="10" x="0.6" y="0.4" z="0.2">
            <origin xyz="0 0 0.1" rpy="0 0 0"/>
        </xacro:inertial_box>
    </link>

   
    <link name="left_wheel_back_link">
        <visual>
            <geometry>
                <cylinder radius="0.1" length="0.05" />
            </geometry>

            <origin xyz="0 0 0" rpy="1.57 0 0"/>
            <material name = "black" />
        </visual>

        <collision>
            <geometry>
                <cylinder radius="0.1" length="0.05" />
            </geometry>

            <origin xyz="0 0 0" rpy="1.57 0 0"/>
        </collision>

        <xacro:inertial_cylinder mass="10" length="0.05" radius="0.1">
            <origin xyz="0 0 0" rpy="1.57 0 0"/>
        </xacro:inertial_cylinder>
    </link>

     

    <joint name="base_left_wheel_back_joint" type="continuous">
        <parent link="base_link" />
        <child link="left_wheel_back_link" />
        <origin xyz="-0.15 0.225 0" rpy="0 0 0"/>
        <axis xyz="0 1 0" />
        <dynamics damping="0.1" friction="0.5"/>
    </joint>

    <link name="right_wheel_back_link">
        <visual>
            <geometry>
                <cylinder radius="0.1" length="0.05" />
            </geometry>

            <origin xyz="0 0 0" rpy="-1.57 0 0"/>
            <material name = "black" />
        </visual>

        <collision>
            <geometry>
                <cylinder radius="0.1" length="0.05" />
            </geometry>

            <origin xyz="0 0 0" rpy="-1.57 0 0"/>
        </collision>

        <xacro:inertial_cylinder mass="10" length="0.05" radius="0.1">
            <origin xyz="0 0 0" rpy="-1.57 0 0"/>
        </xacro:inertial_cylinder>
    </link>

    <joint name="base_right_wheel_back_joint" type="continuous">
        <parent link="base_link" />
        <child link="right_wheel_back_link" />
        <origin xyz="-0.15 -0.225 0" rpy="0 0 0"/>
        <axis xyz="0 1 0" />
        <dynamics damping="0.1" friction="0.5"/>
    </joint>

     <link name="left_wheel_front_link">
        <visual>
            <geometry>
                <cylinder radius="0.1" length="0.05" />
            </geometry>

            <origin xyz="0 0 0" rpy="1.57 0 0"/>
            <material name = "black" />
        </visual>

        <collision>
            <geometry>
                <cylinder radius="0.1" length="0.05" />
            </geometry>

            <origin xyz="0 0 0" rpy="1.57 0 0"/>
        </collision>

        <xacro:inertial_cylinder mass="10" length="0.05" radius="0.1">
            <origin xyz="0 0 0" rpy="1.57 0 0"/>
        </xacro:inertial_cylinder>
    </link>

     

    <joint name="base_left_wheel_front_joint" type="continuous">
        <parent link="base_link" />
        <child link="left_wheel_front_link" />
        <origin xyz="0.15 0.225 0" rpy="0 0 0"/>
        <axis xyz="0 1 0" />
        <dynamics damping="0.1" friction="0.5"/>
    </joint>


    <link name="right_wheel_front_link">
        <visual>
            <geometry>
                <cylinder radius="0.1" length="0.05" />
            </geometry>

            <origin xyz="0 0 0" rpy="-1.57 0 0"/>
            <material name = "black" />
        </visual>

        <collision>
            <geometry>
                <cylinder radius="0.1" length="0.05" />
            </geometry>

            <origin xyz="0 0 0" rpy="-1.57 0 0"/>
        </collision>

        <xacro:inertial_cylinder mass="10" length="0.05" radius="0.1">
            <origin xyz="0 0 0" rpy="-1.57 0 0"/>
        </xacro:inertial_cylinder>
    </link>

    <joint name="base_right_wheel_front_joint" type="continuous">
        <parent link="base_link" />
        <child link="right_wheel_front_link" />
        <origin xyz="0.15 -0.225 0" rpy="0 0 0"/>
        <axis xyz="0 1 0" />
        <dynamics damping="0.1" friction="0.5"/>
    </joint>
</robot>